Workbook
Name CC_originacao: #REF!,#REF!,#REF!,#REF!,#REF!
Name CC_PAC: #REF!,#REF!,#REF!,#REF!,#REF!
Name TAB_EMP: #REF!

Sheet custo unitário INSUMOS
A1: CÓDIGOS | B1: INSUMOS NAS ESTRUTURAS | C1: unidade de compra | D1: vlr unitário | E1: data entrada | F1: NF | G1: Fornecedor | H1: unidade de estoque | I1: vlr unit pela unidade de estoque | J1: vlr unit pela unidade de estoque SEM TRIBUTOS | K1: pis, cofins, icms | L1: pis, cofins
A2: 05.0004 | B2: CAIXA DE ISOPOR (8,5L) | C2: UN | D2: 5.1 | E2: 45462 | F2: 108243 | G2: 12152 | H2: UN | I2: 5.1 | J2: =+I2*$L$4 -> 4.62825 | K2: =1.65+7.6+7 -> 16.25 | L2: =1.65+7.6 -> 9.25
A3: 05.0020 | B3: SACO PLASTICO 1KG - UNICA | C3: MI | D3: 0.073 | E3: 44944 | F3: 1266 | G3: 11312 | H3: UN | I3: 0.073 | J3: =+I3*$L$4 -> 0.0662475 | K3: =100-K2 -> 83.75 | L3: =100-L2 -> 90.75
A4: 05.0032 | B4: SACO GOODFISH 500g | C4: sem entrada com nota fiscal | D4: - | E4: - | F4: - | H4: - | J4: =+I4*$L$4 -> 0 | K4: =+K3/100 -> 0.8375 | L4: =+L3/100 -> 0.9075
A5: 05.0033 | B5: SACO QUALYFISH 400g | C5: sem entrada com nota fiscal | D5: - | E5: - | F5: - | H5: - | J5: =+I5*$L$4 -> 0
A6: 05.0034 | B6: SACO QUALYFISH 800g | C6: sem entrada com nota fiscal | D6: - | E6: - | F6: - | H6: - | J6: =+I6*$L$4 -> 0
A7: 05.0046 | B7: ETQ AZUL | C7: MI | D7: 0.086 | E7: 45379 | F7: 14660 | G7: 10112 | H7: UN | I7: 0.086 | J7: =+I7*$L$4 -> 0.078045
A8: 05.0047 | B8: ETQ VERDE | C8: MI | D8: 0.086 | E8: 45379 | F8: 14660 | G8: 10112 | H8: UN | I8: 0.086 | J8: =+I8*$L$4 -> 0.078045
A9: 05.0048 | B9: ETIQUETA VERMELHA - GG | C9: MI | D9: 0.086 | E9: 45379 | F9: 14660 | G9: 10112 | H9: UN | I9: 0.086 | J9: =+I9*$L$4 -> 0.078045
A10: 05.0049 | B10: ETQ BRANCA | C10: sem entrada com nota fiscal | D10: - | E10: - | F10: - | H10: UN | I10: 0.086 | J10: =+I10*$L$4 -> 0.078045
A11: 05.0073 | B11: SACO PARA CONGELADOS | C11: MI | D11: 0.096 | E11: 45351 | F11: 1846 | G11: 11312 | H11: UN | I11: 0.096 | J11: =+I11*$L$4 -> 0.08712
A12: 05.0080 | B12: CAIXA DE PAPELÃO 330X430X330mm | C12: UN - MI | D12: 6,31 e 5,70 | E12: 45379 | F12: 7275 - 63951 | G12: 13701 - 13433 | H12: UN | I12: 6.2 | J12: =+I12*$L$4 -> 5.6265
A13: 05.0083 | B13: FOLHA PE LISA 30X40 | C13: MI | D13: 0.109 | E13: 45443 | F13: 67524 | G13: 10825 | H13: UN | I13: 0.06 | J13: =+I13*$L$4 -> 0.05445
A14: 05.0086 | B14: RIBBON | C14: RL | D14: =48/300 -> 0.16 | E14: 45350 | F14: 22152 | G14: 14498 | H14: M | I14: =0.032 -> 0.032 | J14: =+I14*$L$4 -> 0.02904
A15: 05.0087 | B15: FITA ADESIVA | C15: RL | D15: =5.6/100 -> 0.056 | E15: 45453 | F15: 7765 | G15: 11427 | H15: M | I15: =5.6/100 -> 0.056 | J15: =+I15*$L$4 -> 0.05082
A16: 05.0088 | B16: ABSORVENTE PRETO | C16: CX | D16: 0.096 | E16: 45379 | F16: 8617 | G16: 10212 | H16: UN | I16: 0.096 | J16: =+I16*$L$4 -> 0.08712
A17: 05.0092 | B17: ABSORVENTE BRANCO | C17: CX | D17: 0.064 | E17: 45264 | F17: 8156 | G17: 10212 | H17: UN | I17: 0.064 | J17: =+I17*$L$4 -> 0.05808
A18: 05.0089 | B18: FITA DE ARQUEAR | C18: RL | D18: =320/3000 -> 0.10666667 | E18: 45350 | F18: 128237 | G18: 11413 | H18: M | I18: =320/3000 -> 0.10666667 | J18: =+I18*$L$4 -> 0.0968
A19: 05.0090 | B19: SACO 500X800X0,16 AZUL | C19: MI | D19: 1.233 | E19: 44812 | F19: 14904 | G19: 12851 | H19: UN | I19: 1.233 | J19: =+I19*$L$4 -> 1.1189475
A20: 05.0091 | B20: SACO RAFIA | C20: SC | D20: 1.45 | E20: 45240 | F20: 286 | G20: 13057 | H20: UN | I20: 1.45 | J20: =+I20*$L$4 -> 1.315875
A21: 05.0059 | B21: SACO QUALY NP 350X450X120P | C21: MI | D21: =10584/10000 -> 1.0584 | E21: 45381 | F21: 1363 | G21: 11312 | H21: UN | I21: =10584/10000 -> 1.0584 | J21: =+I21*$L$4 -> 0.960498
A22: 04.0018 | B22: GELOX | C22: UNIDADE | I22: =SUM(I23:I24) -> 0.5532408 | J22: =+I22*$L$4 -> 0.50206603
A23: 05.0093 | B23: PO QUIMICO GEL PACK - UNICA | C23: KG | D23: =13.0208/1000 -> 0.0130208 | E23: 45412 | F23: 15158 | G23: 12519 | H23: GR | I23: =13.0208/1000 -> 0.0130208 | J23: =+I23*$L$4 -> 0.011816376
A24: 05.0017 | B24: SACO GEL PACK - UNICA | C24: MI | D24: =540.22/1000 -> 0.54022 | E24: 45462 | F24: 2054 | G24: 11312 | H24: UN | I24: =540.22/1000 -> 0.54022 | J24: =+I24*$L$4 -> 0.49024965
A25: 05.0027 | B25: PEIXE VIVO | C25: KG | D25: 1 | H25: KG | I25: 7.79 | J25: =+I25*$L$4 -> 7.069425
A26: FLR001 | B26: FILE SEM PELE IN NATURA | C26: RENDIMENTO/KG | D26: 0.33 | H26: KG | I26: =(D25/D26)*I25 -> 23.606061 | J26: =+I26*$L$4 -> 21.4225
A27: 04.0015 | B27: RESÍDUO | C27: RENDIMENTO/KG | D27: 0.67 | H27: KG | I27: =(D25/D27)*I25 -> 11.626866 | J27: =+I27*$L$4 -> 10.551381
A28: EVISCERADA | B28: EVICESRADA | C28: RENDIMENTO/KG | D28: 0.95 | H28: KG | I28: =(D25/D28)*I25 -> 8.2 | J28: =+I28*$L$4 -> 7.4415

Sheet estruturas MODELOS
B1: BASE ATUALIZADA EM: | C1: 45471
A3: Código | B3: Derivação | C3: Unid | D3: Qtde | E3: Custo por PA | F3: Custo por KG
A5: RESFRIADOS
B6: DIVERSOS
A7: DERIVACAO EMB005 | B7: CAIXA DE ISOPOR 5kg | C7: PA - 5KG | D7: 5
A8: FLR001 | B8: FILÉ SEM PELE IN NATURA | C8: KG - RENDIMENTO | D8: 0.33 | E8: =VLOOKUP(A8,'custo unitário INSUMOS'!A:J,11,0)*D7 -> #REF!
A9: 05.0004 | B9: CAIXA DE ISOPOR (8,5L) | C9: unidade | D9: 1 | E9: =VLOOKUP(A9,'custo unitário INSUMOS'!A:J,11,0)*D9 -> #REF!
A10: 04.0018 | B10: GELOX | C10: unidade | D10: 1 | E10: =VLOOKUP(A10,'custo unitário INSUMOS'!A:J,11,0)*D10 -> #REF!
A11: 05.0083 | B11: FOLHA PE LISA 30X40 | C11: unidades | D11: 3 | E11: =VLOOKUP(A11,'custo unitário INSUMOS'!A:J,11,0)*D11 -> #REF!
A12: 05.0086 | B12: RIBBON | C12: metros | D12: =17/100 -> 0.17 | E12: =VLOOKUP(A12,'custo unitário INSUMOS'!A:J,11,0)*D12 -> #REF!
A13: 05.0087 | B13: FITA ADESIVA | C13: metros | D13: 1.35 | E13: =VLOOKUP(A13,'custo unitário INSUMOS'!A:J,11,0)*D13 -> #REF!
A14: 05.0048 | B14: ETIQUETA VERMELHA - GG | C14: unidade | D14: 1 | E14: =VLOOKUP(A14,'custo unitário INSUMOS'!A:J,11,0)*D14 -> #REF!
A15: 05.0088 | B15: ABSORVENTE PRETO | C15: unidade | D15: 1 | E15: =VLOOKUP(A15,'custo unitário INSUMOS'!A:J,11,0)*D15 -> #REF!
A16: OU
A17: 05.0092 | B17: ABSORVENTE BRANCO | C17: unidade | D17: 2 | E17: =VLOOKUP(A17,'custo unitário INSUMOS'!A:J,11,0)*D17 -> #REF!
C19: c/ ABS PRETO | D19: Custo | E19: =SUM(E8:E15) -> #REF! | F19: =+E19/D7 -> #REF!
C20: c/ ABS BRANCO | D20: Custo | E20: =SUM(E8:E14,E17) -> #REF! | F20: =+E20/D7 -> #REF!
E21: PA | F21: KG
A23: 02.0030 | B23: FILE DE TILAPIA RESFR. 100 UP MRN - VACUO 1KG
A24: DERIVAÇÃO EMB001 | B24: SACO À VÁCUO 1KG | C24: PA - 1KG | D24: 1
A25: FLR001 | B25: FILÉ SEM PELE IN NATURA | C25: KG - RENDIMENTO | D25: =+D8 -> 0.33 | E25: =VLOOKUP(A25,'custo unitário INSUMOS'!A:J,11,0)*D24 -> #REF!
A26: 05.0086 | B26: RIBBON | C26: metros | D26: =17/100 -> 0.17 | E26: =VLOOKUP(A26,'custo unitário INSUMOS'!A:J,11,0)*D26 -> #REF!
A27: 05.0048 | B27: ETIQUETA (unidades) | C27: unidade | D27: 1 | E27: =VLOOKUP(A27,'custo unitário INSUMOS'!A:J,11,0)*D27 -> #REF!
A28: 05.0020 | B28: SACO PLASTICO 1KG - UNICA | C28: unidade | D28: 1 | E28: =VLOOKUP(A28,'custo unitário INSUMOS'!A:J,11,0)*D28 -> #REF!
D30: Custo | E30: =SUM(E25:E28) -> #REF! | F30: =+E30/D24 -> #REF!
E31: PA | F31: KG
A32: sem faturamento em 2023
A33: DERIVAÇÃO EMB009 | B33: CAIXA DE PAPELÃO 15KG - RESFRIADO | C33: PA - 15KG | D33: 15
A34: FLR001 | B34: FILÉ SEM PELE IN NATURA | C34: KG - RENDIMENTO | D34: =+D8 -> 0.33 | E34: =VLOOKUP(A34,'custo unitário INSUMOS'!A:J,11,0)*D33 -> #REF!
A35: 05.0080 | B35: CAIXA DE PAPELÃO 330X430X330mm | C35: unidade | D35: 1 | E35: =VLOOKUP(A35,'custo unitário INSUMOS'!A:J,11,0)*D35 -> #REF!
A36: 05.0059 | B36: SACO QUALY NP 350 X 450 X 120P | C36: unidade | D36: 3 | E36: =VLOOKUP(A36,'custo unitário INSUMOS'!A:J,11,0)*D36 -> #REF!
A37: 05.0086 | B37: RIBBON | C37: metros | D37: =(17/100)*D39 -> 0.68 | E37: =VLOOKUP(A37,'custo unitário INSUMOS'!A:J,11,0)*D37 -> #REF!
A38: 05.0089 | B38: FITA DE ARQUEAR | C38: metros | D38: 2.68 | E38: =VLOOKUP(A38,'custo unitário INSUMOS'!A:J,11,0)*D38 -> #REF!
A39: 05.0048 | B39: ETIQUETA (unidades) | C39: unidade | D39: 4 | E39: =VLOOKUP(A39,'custo unitário INSUMOS'!A:J,11,0)*D39 -> #REF!
D41: Custo | E41: =SUM(E34:E39) -> #REF! | F41: =+E41/D33 -> #REF!
E42: PA | F42: KG
A43: sem faturamento em 2023
A44: DERIVAÇÃO EMB011 | B44: CAIXA DE PAPELÃO 30KG | C44: PA | D44: 30
A45: FLR001 | B45: FILÉ SEM PELE IN NATURA | C45: KG - RENDIMENTO | D45: =+D8 -> 0.33 | E45: =VLOOKUP(A45,'custo unitário INSUMOS'!A:J,11,0)*D44 -> #REF!
A46: 05.0080 | B46: CAIXA DE PAPELÃO 330X430X330mm | C46: unidade | D46: 1 | E46: =VLOOKUP(A46,'custo unitário INSUMOS'!A:J,11,0)*D46 -> #REF!
...
