Workbook
Name CC_originacao: #REF!,#REF!,#REF!,#REF!,#REF!
Name CC_PAC: #REF!,#REF!,#REF!,#REF!,#REF!
Name TAB_EMP: #REF!

Sheet custo unitário INSUMOS
A1: CÓDIGOS ANTIGO | B1: CÓDIGOS | C1: INSUMOS NAS ESTRUTURAS | D1: unidade de compra | E1: vlr unitário | F1: data entrada | G1: NF | H1: Fornecedor | J1: unidade de estoque | K1: vlr unit pela unidade de estoque | L1: vlr unit pela unidade de estoque SEM TRIBUTOS | O1: pis, cofins, icms | P1: pis, cofins
B2: 05.0004 | C2: CAIXA DE ISOPOR (8,5L) | D2: UN | E2: 5.1 | F2: 45462 | G2: 108243 | H2: 12152 | J2: UN | K2: 5.1 | L2: =+K2*$P$4 -> 4.62825 | O2: =1.65+7.6+7 -> 16.25 | P2: =1.65+7.6 -> 9.25
B3: 05.0020 | C3: SACO PLASTICO 1KG - UNICA | D3: MI | E3: 0.073 | F3: 44944 | G3: 1266 | H3: 11312 | J3: UN | K3: 0.073 | L3: =+K3*$P$4 -> 0.0662475 | O3: =100-O2 -> 83.75 | P3: =100-P2 -> 90.75
B4: 05.0032 | C4: SACO GOODFISH 500g | D4: sem entrada com nota fiscal | E4: - | F4: - | G4: - | J4: - | L4: =+K4*$P$4 -> 0 | O4: =+O3/100 -> 0.8375 | P4: =+P3/100 -> 0.9075
B5: 05.0033 | C5: SACO QUALYFISH 400g | D5: sem entrada com nota fiscal | E5: - | F5: - | G5: - | J5: - | L5: =+K5*$P$4 -> 0
B6: 05.0034 | C6: SACO QUALYFISH 800g | D6: sem entrada com nota fiscal | E6: - | F6: - | G6: - | J6: - | L6: =+K6*$P$4 -> 0
B7: 05.0046 | C7: ETQ AZUL | D7: MI | E7: 0.086 | F7: 45379 | G7: 14660 | H7: 10112 | J7: UN | K7: 0.086 | L7: =+K7*$P$4 -> 0.078045
B8: 05.0047 | C8: ETQ VERDE | D8: MI | E8: 0.086 | F8: 45379 | G8: 14660 | H8: 10112 | J8: UN | K8: 0.086 | L8: =+K8*$P$4 -> 0.078045
B9: 05.0048 | C9: ETIQUETA VERMELHA - GG | D9: MI | E9: 0.086 | F9: 45379 | G9: 14660 | H9: 10112 | J9: UN | K9: 0.086 | L9: =+K9*$P$4 -> 0.078045
B10: 05.0049 | C10: ETQ BRANCA | D10: sem entrada com nota fiscal | E10: - | F10: - | G10: - | J10: UN | K10: 0.086 | L10: =+K10*$P$4 -> 0.078045
B11: 05.0073 | C11: SACO PARA CONGELADOS | D11: MI | E11: 0.096 | F11: 45351 | G11: 1846 | H11: 11312 | J11: UN | K11: 0.096 | L11: =+K11*$P$4 -> 0.08712
B12: 05.0080 | C12: CAIXA DE PAPELÃO 330X430X330mm | D12: UN - MI | E12: 6,31 e 5,70 | F12: 45379 | G12: 7275 - 63951 | H12: 13701 - 13433 | J12: UN | K12: 6.2 | L12: =+K12*$P$4 -> 5.6265
B13: 05.0083 | C13: FOLHA PE LISA 30X40 | D13: MI | E13: 0.109 | F13: 45443 | G13: 67524 | H13: 10825 | J13: UN | K13: 0.06 | L13: =+K13*$P$4 -> 0.05445
A14: 05.0078 | B14: 05.0086 | C14: RIBBON | D14: RL | E14: =48/300 -> 0.16 | F14: 45350 | G14: 22152 | H14: 14498 | I14: Conversão baseada cada rolo com 300 mt (110mm X 300mt) | J14: M | K14: =0.032 -> 0.032 | L14: =+K14*$P$4 -> 0.02904
A15: 05.0061 | B15: 05.0087 | C15: FITA ADESIVA | D15: RL | E15: =5.6/100 -> 0.056 | F15: 45453 | G15: 7765 | H15: 11427 | I15: Conversão baseada cada rolo com 100 mt (FITA ADESIVA HM 45MM X 100M) | J15: M | K15: =5.6/100 -> 0.056 | L15: =+K15*$P$4 -> 0.05082
A16: 05.0015 | B16: 05.0088 | C16: ABSORVENTE PRETO | D16: CX | E16: 0.096 | F16: 45379 | G16: 8617 | H16: 10212 | I16: Conversão baseada cada cx 2000 unidades | J16: UN | K16: 0.096 | L16: =+K16*$P$4 -> 0.08712
B17: 05.0092 | C17: ABSORVENTE BRANCO | D17: CX | E17: 0.064 | F17: 45264 | G17: 8156 | H17: 10212 | I17: Conversão baseada cada cx 3000 unidades | J17: UN | K17: 0.064 | L17: =+K17*$P$4 -> 0.05808
A18: 05.0075 | B18: 05.0089 | C18: FITA DE ARQUEAR | D18: RL | E18: =320/3000 -> 0.10666667 | F18: 45350 | G18: 128237 | H18: 11413 | I18: Conversão baseada cada rolo com 3000 mt (FITA SOLDA 10X0,65 MM 3000 BRANCA) | J18: M | K18: =320/3000 -> 0.10666667 | L18: =+K18*$P$4 -> 0.0968
A19: 05.0050 | B19: 05.0090 | C19: SACO 500X800X0,16 AZUL | D19: MI | E19: 1.233 | F19: 44812 | G19: 14904 | H19: 12851 | J19: UN | K19: 1.233 | L19: =+K19*$P$4 -> 1.1189475
A20: 06.1131 | B20: 05.0091 | C20: SACO RAFIA | D20: SC | E20: 1.45 | F20: 45240 | G20: 286 | H20: 13057 | J20: UN | K20: 1.45 | L20: =+K20*$P$4 -> 1.315875
B21: 05.0059 | C21: SACO QUALY NP 350X450X120P | D21: MI | E21: =10584/10000 -> 1.0584 | F21: 45381 | G21: 1363 | H21: 11312 | J21: UN | K21: =10584/10000 -> 1.0584 | L21: =+K21*$P$4 -> 0.960498
B23: 04.0018 | C23: GELOX | D23: UNIDADE | K23: =SUM(K24:K25) -> 0.5532408 | L23: =+K23*$P$4 -> 0.50206603
A24: 05.0019 | B24: 05.0093 | C24: PO QUIMICO GEL PACK - UNICA | D24: KG | E24: =13.0208/1000 -> 0.0130208 | F24: 45412 | G24: 15158 | H24: 12519 | J24: GR | K24: =13.0208/1000 -> 0.0130208 | L24: =+K24*$P$4 -> 0.011816376
B25: 05.0017 | C25: SACO GEL PACK - UNICA | D25: MI | E25: =540.22/1000 -> 0.54022 | F25: 45462 | G25: 2054 | H25: 11312 | J25: UN | K25: =540.22/1000 -> 0.54022 | L25: =+K25*$P$4 -> 0.49024965
B27: 05.0027 | C27: PEIXE VIVO | D27: KG | E27: 1 | J27: 1 KG DE PEIXE | K27: 7.79 | L27: =+K27*$P$4 -> 7.069425
B28: FLR001 | C28: FILE SEM PELE IN NATURA | D28: RENDIMENTO/KG | E28: =+'estruturas MODELOS'!D8 -> 0.33 | J28: 1 KG DE FILÉ | K28: =(E27/E28)*K27 -> 23.606061 | L28: =+K28*$P$4 -> 21.4225
B29: 04.0015 | C29: RESÍDUO | D29: RENDIMENTO/KG | E29: =+E27-E28 -> 0.67 | J29: 1 KG DE RESÍDUO | K29: =(E27/E29)*K27 -> 11.626866 | L29: =+K29*$P$4 -> 10.551381
B30: EVISCERADA | C30: EVICESRADA | D30: RENDIMENTO/KG | E30: 0.95 | J30: 1 KG DE PEIXE | K30: =(E27/E30)*K27 -> 8.2 | L30: =+K30*$P$4 -> 7.4415

Sheet estruturas MODELOS
B1: BASE ATUALIZADA EM: | C1: 45471
A3: Código | B3: Derivação | C3: Unid | D3: Qtde | E3: Custo por PA | F3: Custo por KG
A5: RESFRIADOS
B6: DIVERSOS
A7: DERIVACAO EMB005 | B7: CAIXA DE ISOPOR 5kg | C7: PA - 5KG | D7: 5
A8: FLR001 | B8: FILÉ SEM PELE IN NATURA | C8: KG - RENDIMENTO | D8: 0.33 | E8: =VLOOKUP(A8,'custo unitário INSUMOS'!B:L,11,0)*D7 -> 107.1125
A9: 05.0004 | B9: CAIXA DE ISOPOR (8,5L) | C9: unidade | D9: 1 | E9: =VLOOKUP(A9,'custo unitário INSUMOS'!B:L,11,0)*D9 -> 4.62825
A10: 04.0018 | B10: GELOX | C10: unidade | D10: 1 | E10: =VLOOKUP(A10,'custo unitário INSUMOS'!B:L,11,0)*D10 -> 0.50206603
A11: 05.0083 | B11: FOLHA PE LISA 30X40 | C11: unidades | D11: 3 | E11: =VLOOKUP(A11,'custo unitário INSUMOS'!B:L,11,0)*D11 -> 0.16335
A12: 05.0086 | B12: RIBBON | C12: metros | D12: =17/100 -> 0.17 | E12: =VLOOKUP(A12,'custo unitário INSUMOS'!B:L,11,0)*D12 -> 0.0049368
A13: 05.0087 | B13: FITA ADESIVA | C13: metros | D13: 1.35 | E13: =VLOOKUP(A13,'custo unitário INSUMOS'!B:L,11,0)*D13 -> 0.068607
A14: 05.0048 | B14: ETIQUETA VERMELHA - GG | C14: unidade | D14: 1 | E14: =VLOOKUP(A14,'custo unitário INSUMOS'!B:L,11,0)*D14 -> 0.078045
A15: 05.0088 | B15: ABSORVENTE PRETO | C15: unidade | D15: 1 | E15: =VLOOKUP(A15,'custo unitário INSUMOS'!B:L,11,0)*D15 -> 0.08712
A16: OU
A17: 05.0092 | B17: ABSORVENTE BRANCO | C17: unidade | D17: 2 | E17: =VLOOKUP(A17,'custo unitário INSUMOS'!B:L,11,0)*D17 -> 0.11616
C19: c/ ABS PRETO | D19: Custo | E19: =SUM(E8:E15) -> 112.64487 | F19: =+E19/D7 -> 22.528975
C20: c/ ABS BRANCO | D20: Custo | E20: =SUM(E8:E14,E17) -> 112.67391 | F20: =+E20/D7 -> 22.534783
E21: PA | F21: KG
A23: 02.0030 | B23: FILE DE TILAPIA RESFR. 100 UP MRN - VACUO 1KG
A24: DERIVAÇÃO EMB001 | B24: SACO À VÁCUO 1KG | C24: PA - 1KG | D24: 1
A25: FLR001 | B25: FILÉ SEM PELE IN NATURA | C25: KG - RENDIMENTO | D25: =+D8 -> 0.33 | E25: =VLOOKUP(A25,'custo unitário INSUMOS'!B:L,11,0)*D24 -> 21.4225
A26: 05.0086 | B26: RIBBON | C26: metros | D26: =17/100 -> 0.17 | E26: =VLOOKUP(A26,'custo unitário INSUMOS'!B:L,11,0)*D26 -> 0.0049368
A27: 05.0048 | B27: ETIQUETA (unidades) | C27: unidade | D27: 1 | E27: =VLOOKUP(A27,'custo unitário INSUMOS'!B:L,11,0)*D27 -> 0.078045
A28: 05.0020 | B28: SACO PLASTICO 1KG - UNICA | C28: unidade | D28: 1 | E28: =VLOOKUP(A28,'custo unitário INSUMOS'!B:L,11,0)*D28 -> 0.0662475
D30: Custo | E30: =SUM(E25:E28) -> 21.571729 | F30: =+E30/D24 -> 21.571729
E31: PA | F31: KG
A32: sem faturamento em 2023
A33: DERIVAÇÃO EMB009 | B33: CAIXA DE PAPELÃO 15KG - RESFRIADO | C33: PA - 15KG | D33: 15
A34: FLR001 | B34: FILÉ SEM PELE IN NATURA | C34: KG - RENDIMENTO | D34: =+D8 -> 0.33 | E34: =VLOOKUP(A34,'custo unitário INSUMOS'!B:L,11,0)*D33 -> 321.3375
A35: 05.0080 | B35: CAIXA DE PAPELÃO 330X430X330mm | C35: unidade | D35: 1 | E35: =VLOOKUP(A35,'custo unitário INSUMOS'!B:L,11,0)*D35 -> 5.6265
A36: 05.0059 | B36: SACO QUALY NP 350 X 450 X 120P | C36: unidade | D36: 3 | E36: =VLOOKUP(A36,'custo unitário INSUMOS'!B:L,11,0)*D36 -> 2.881494
A37: 05.0086 | B37: RIBBON | C37: metros | D37: =(17/100)*D39 -> 0.68 | E37: =VLOOKUP(A37,'custo unitário INSUMOS'!B:L,11,0)*D37 -> 0.0197472
A38: 05.0089 | B38: FITA DE ARQUEAR | C38: metros | D38: 2.68 | E38: =VLOOKUP(A38,'custo unitário INSUMOS'!B:L,11,0)*D38 -> 0.259424
A39: 05.0048 | B39: ETIQUETA (unidades) | C39: unidade | D39: 4 | E39: =VLOOKUP(A39,'custo unitário INSUMOS'!B:L,11,0)*D39 -> 0.31218
D41: Custo | E41: =SUM(E34:E39) -> 330.43685 | F41: =+E41/D33 -> 22.029123
E42: PA | F42: KG
A43: sem faturamento em 2023
A44: DERIVAÇÃO EMB011 | B44: CAIXA DE PAPELÃO 30KG | C44: PA | D44: 30
A45: FLR001 | B45: FILÉ SEM PELE IN NATURA | C45: KG - RENDIMENTO | D45: =+D8 -> 0.33 | E45: =VLOOKUP(A45,'custo unitário INSUMOS'!B:L,11,0)*D44 -> 642.675
A46: 05.0080 | B46: CAIXA DE PAPELÃO 330X430X330mm | C46: unidade | D46: 1 | E46: =VLOOKUP(A46,'custo unitário INSUMOS'!B:L,11,0)*D46 -> 5.6265
...

Sheet CUSTO 2024
C1: VENDAS | D1: 45292 | E1: 45323 | F1: 45352 | G1: 45383 | H1: 45413 | I1: 45444 | J1: 45474 | K1: 45505 | L1: 45536 | M1: 45566 | N1: 45597 | O1: 45627 | P1: TOTAL PESO BRUTO
C2: PAC001 | I2: 8880 | J2: 10000 | K2: 33505.6 | P2: =SUM(D2:O2) -> 52385.6
C3: TILAPIA INTEIRA FRESCA - CAIXA PLASTICA 20KG | I3: 8880 | J3: 10000 | K3: 33505.6 | P3: =SUM(D3:O3) -> 52385.6
C4: PAC002 | D4: 28.68 | E4: 17.1 | F4: 30.209 | G4: 14.395 | H4: 338.395 | I4: 234.437 | J4: 288.591 | K4: 763.467 | P4: =SUM(D4:O4) -> 1715.274
C5: TILAPIA INTEIRA EVISC. C/ ESCAMA FRESCA | H5: 330 | I5: 220 | J5: 270 | K5: 329.3 | P5: =SUM(D5:O5) -> 1149.3
C6: TILAPIA INTEIRA EVISC. S/ ESCAMA FRESCA | D6: 28.68 | E6: 17.1 | F6: 30.209 | G6: 14.395 | H6: 8.395 | I6: 14.437 | J6: 10.97 | K6: 16.3 | P6: =SUM(D6:O6) -> 140.486
C7: TILAPIA INTEIRA EVISC. S/ ESCAMA FRESCA - A VACUO 1KG | D7: 0 | E7: 0 | F7: 0 | G7: 0 | H7: 0 | I7: 0 | J7: 7.621 | P7: =SUM(D7:O7) -> 7.621
C8: TILAPIA EVISCERADA RESFRIADA - PAPELAO 30KG | D8: 0 | E8: 0 | F8: 0 | G8: 0 | H8: 0 | I8: 0 | J8: 0 | K8: 105
C9: TILAPIA EVISCERADA RESFRIADA | D9: 0 | E9: 0 | F9: 0 | G9: 0 | H9: 0 | I9: 0 | J9: 0 | K9: 12.867
C10: TILAPIA EVISCERADA RESFRIADA C/ ESCAMA | D10: 0 | E10: 0 | F10: 0 | G10: 0 | H10: 0 | I10: 0 | J10: 0 | K10: 300
C11: PAC003 | F11: 10 | J11: 4.77 | K11: 82557.76 | P11: =SUM(D11:O11) -> 82572.53
C12: TILAPIA INTEIRA ESPALMADA CONGELADA | F12: 10 | P12: =SUM(D12:O12) -> 10
C13: TILAPIA INTEIRA EVISC. C/ ESCAMA CONG. - VACUO 1KG | D13: 0 | E13: 0 | F13: 0 | G13: 0 | H13: 0 | I13: 0 | J13: 4.77
C14: WHOLE BLACK TILAPIA 350/550 GRAMS - PAPELAO 30KG | D14: 0 | E14: 0 | F14: 0 | G14: 0 | H14: 0 | I14: 0 | J14: 0 | K14: 10569.12
C15: WHOLE BLACK TILAPIA 550/750 GRAMS - PAPELAO 30KG | D15: 0 | E15: 0 | F15: 0 | G15: 0 | H15: 0 | I15: 0 | J15: 0 | K15: 60981.28
C16: WHOLE BLACK TILAPIA 750/950 GRAMS - PAPELAO 30KG | D16: 0 | E16: 0 | F16: 0 | G16: 0 | H16: 0 | I16: 0 | J16: 0 | K16: 9007.36
C17: TILAPIA INTEIRA EVISC. S/ ESCAMA CONG. - PAPELAO 20KG | D17: 0 | E17: 0 | F17: 0 | G17: 0 | H17: 0 | I17: 0 | J17: 0 | K17: 2000
C18: PAC006 | D18: 1866 | E18: 15696 | F18: 16645 | G18: 3190 | H18: 12538 | I18: 44124 | J18: 269408 | K18: 264625 | P18: =SUM(D18:O18) -> 628092
C19: CARCACA FRESCA - A GRANEL - GRANEL | I19: 41440 | J19: 262100 | K19: 246830 | P19: =SUM(D19:O19) -> 550370
C20: FILE DE TILAPIA CONG. 100G UP PRN | E20: 30 | F20: 105 | G20: 900 | H20: 1140 | I20: 1020 | J20: 5895 | K20: 12580 | P20: =SUM(D20:O20) -> 21670
C21: FILE DE TILAPIA CONG. 70G UP PRN - PAPELAO 15KG | D21: 660 | E21: 7740 | F21: 16455 | G21: 2275 | H21: 11370 | I21: 1350 | J21: 1050 | K21: 450 | P21: =SUM(D21:O21) -> 41350
C22: FILE DE TILAPIA CONG. G 130/180G MRN | D22: 10 | E22: 10 | F22: 47 | G22: 15 | H22: 28 | I22: 62 | P22: =SUM(D22:O22) -> 172
C23: FILE DE TILAPIA CONG. G 130/180G MRN - SACO 1KG - VACUO 1KG | I23: 3 | J23: 17 | K23: 31 | P23: =SUM(D23:O23) -> 51
C24: FILE DE TILAPIA CONG. GG 180G UP MRN | F24: 38 | I24: 9 | P24: =SUM(D24:O24) -> 47
C25: FILE DE TILAPIA CONG. QUALYFISH 400G | D25: 620 | E25: 860 | P25: =SUM(D25:O25) -> 1480
C26: FILE DE TILAPIA CONG. QUALYFISH 800G | D26: 576 | E26: 7056 | I26: 240 | J26: 336 | K26: 288 | P26: =SUM(D26:O26) -> 8496
C27: FILE DE TILAPIA CONG. G 130/180G MRN - VACUO 5KG | D27: 0 | E27: 0 | F27: 0 | G27: 0 | H27: 0 | I27: 0 | J27: 10 | K27: 46
C28: FILE DE TILAPIA CONG. 100G PRN - PAPELAO 15KG | D28: 0 | E28: 0 | F28: 0 | G28: 0 | H28: 0 | I28: 0 | J28: 0 | K28: 4400
C29: PAC007 | D29: 150101 | E29: 147736 | F29: 126979 | G29: 101343 | H29: 90651 | I29: 91429 | J29: 114742 | K29: 153043.8 | P29: =SUM(D29:O29) -> 976024.8
C30: FILE DE TILAPIA RESFR. 100 UP MRN | D30: 12755 | E30: 10910 | F30: 6510 | G30: 8745 | H30: 6020 | I30: 3460 | J30: 3220 | K30: 3290 | P30: =SUM(D30:O30) -> 54910
C31: FILE DE TILAPIA RESFR. 100 UP PRN | D31: 86898 | E31: 82170 | F31: 78532 | G31: 52630 | H31: 47270 | I31: 35875 | J31: 37130 | K31: 43130 | P31: =SUM(D31:O31) -> 463635
C32: FILE DE TILAPIA RESFR. 100 UP PRN - A VACUO 1KG | I32: 2 | J32: 1 | K32: 2 | P32: =SUM(D32:O32) -> 5
C33: FILE DE TILAPIA RESFR. 100 UP PRN - CX 30KG | I33: 930 | J33: 2130 | K33: 3150 | P33: =SUM(D33:O33) -> 6210
C34: FILE DE TILAPIA RESFR. 100 UP PRN M&R - ISOPOR 5KG | I34: 3510 | J34: 6005 | K34: 6500 | P34: =SUM(D34:O34) -> 16015
C35: FILE DE TILAPIA RESFR. 70G UP MRN | G35: 455 | P35: =SUM(D35:O35) -> 455
C36: FILE DE TILAPIA RESFR. 70G UP PRN | F36: 1665 | G36: 775 | P36: =SUM(D36:O36) -> 2440
C37: FILE DE TILAPIA RESFR. G 130/180G MRN | D37: 28203 | E37: 27526 | F37: 22542 | G37: 25818 | H37: 21881 | I37: 14221 | J37: 5990 | K37: 4270 | P37: =SUM(D37:O37) -> 150451
C38: FILE DE TILAPIA RESFR. G 130/180G MRN - A VACUO 1KG | I38: 11 | J38: 48 | K38: 36 | P38: =SUM(D38:O38) -> 95
C39: FILE DE TILAPIA RESFR. G 130/180G MRN M&R - ISOPOR 5KG | I39: 3590 | J39: 11000 | K39: 20710 | P39: =SUM(D39:O39) -> 35300
C40: FILE DE TILAPIA RESFR. G 130/180G PRN | D40: 300 | P40: =SUM(D40:O40) -> 300
...

Sheet Planilha2
A1: PAC007 | B1: EMB005 | C1: RESFRIADO | E1: $ | G1: PELE SACO 12 KG
A2: FLR001 | B2: FILÉ SEM PELE IN NATURA | C2: kg | D2: 5 | E2: =(8.02*37%)*D2 -> 14.837 | G2: 04.0015 | H2: RESÍDUO | I2: kg | J2: 12
A3: 05.0004 | B3: CAIXA DE ISOPOR (8,5L) | C3: unidade | D3: 1 | E3: 5.35 | G3: 05.0086 | H3: RIBBON | I3: metros | J3: 0,17
A4: 05.0083 | B4: FOLHA PE LISA 30X40 | C4: unidades | D4: 3 | E4: =D4*0.06 -> 0.18 | H4: ETIQUETA | I4: unidade | J4: 1
A5: 05.0086 | B5: RIBBON | C5: metros | D5: 0,17 | E5: =D5*0.003 -> 0.00051 | G5: 05.0090 | H5: SACO 500X800X0,16 AZUL | I5: unidade | J5: 1
A6: 05.0087 | B6: FITA ADESIVA | C6: metros | D6: 1,25 | E6: =D6*0.057 -> 0.07125
B7: ETIQUETA | C7: unidade | D7: 1 | E7: =D7*0.1863 -> 0.1863
A8: 05.0092 | B8: ABSORVENTE BRANCO | C8: unidade | D8: 3 | E8: =D8*0.072 -> 0.216 | G8: VENTRECHA CONGELADA SACO 12 KG
B9: SACO GELOX | C9: unidades | D9: 1 | E9: =D9*0.074 -> 0.074 | G9: 04.0015 | H9: RESÍDUO | I9: kg | J9: 12
B10: PÓ GEL (GELOX) | C10: gramas | D10: 0,175 | E10: =D10*0.0002 -> 3.5e-05 | G10: 05.0086 | H10: RIBBON | I10: metros | J10: 0,17
E11: =SUM(E2:E10) -> 20.915095 | F11: =(161880/5)*E11 -> 677147.12 | H11: ETIQUETA | I11: unidade | J11: 1
A12: PAC007 | B12: EMB011 | C12: RESFRIADO | G12: 05.0090 | H12: SACO 500X800X0,16 AZUL | I12: unidade | J12: 1
A13: FLR001 | B13: FILÉ SEM PELE IN NATURA | C13: kg | D13: 30
A14: 05.0080 | B14: CAIXA DE PAPELÃO 330X430X330mm | C14: unidade | D14: 1
A15: 05.0059 | B15: SACO QUALY NP 350 X 450 X 120P | C15: unidade | D15: 6 | G15: BARRIGUINHA CONGELADA SACO 12 KG
A16: 05.0086 | B16: RIBBON | C16: metros | D16: 1,19 | G16: 04.0015 | H16: RESÍDUO | I16: kg | J16: 12
A17: 05.0089 | B17: FITA DE ARQUEAR | C17: metros | D17: 2,68 | G17: 05.0086 | H17: RIBBON | I17: metros | J17: 0,17
B18: ETIQUETA (unidades) | C18: unidade | D18: 7 | H18: ETIQUETA | I18: unidade | J18: 1
G19: 05.0090 | H19: SACO 500X800X0,16 AZUL | I19: unidade | J19: 1
A20: PAC009 | B20: EMB001 | C20: RESFRIADO
A21: FLR001 | B21: FILÉ SEM PELE IN NATURA | C21: kg | D21: 1
A22: 05.0059 | B22: SACO PLASTICO 1KG - UNICA | C22: unidade | D22: 1 | G22: PAC001 | H22: TILÁPIA INTEIRA NO GELO
A23: 05.0086 | B23: RIBBON | C23: metros | D23: 0,17 | G23: 03.0005 | H23: TILAPIA INTEIRA FRESCA | I23: kg | J23: 20
B24: ETIQUETA (unidades) | C24: unidade | D24: 1 | G24: 05.0086 | H24: RIBBON | I24: metros | J24: 0,17
H25: ETIQUETA | I25: unidade | J25: 1
A26: PAC006 | B26: EMB009 | C26: CONGELADO | H26: GELO | I26: kg | J26: 15
A27: FLR001 | B27: FILÉ SEM PELE IN NATURA | C27: kg | D27: 15
A28: 05.0080 | B28: CAIXA DE PAPELÃO 330X430X330mm | C28: unidade | D28: 1
A29: 05.0073 | B29: SACO PARA CONGELADOS | C29: unidade | D29: 3
A30: 05.0086 | B30: RIBBON | C30: metros | D30: 0,68
A31: 05.0089 | B31: FITA DE ARQUEAR | C31: metros | D31: 2,68
B32: ETIQUETA (unidades) | C32: unidade | D32: 4
